Workbook

Sheet TC_Portfolio
A1: 컴투스프로야구2026 QA Test Case Portfolio
A2: 초반 플레이 루프 기반 모바일 게임 QA 테스트케이스
A4: 테스트 대상 | B4: 컴투스프로야구2026 리그 초반 플레이 루프 | E4: 테스트 방식 | F4: 수동 테스트 기반 TC 작성 및 실행 | I4: 입력 방식 | J4: 터치 | L4: 작성자 | M4: 정재우
A5: 테스트 범위 | B5: 로비 · 환경설정 · 이벤트/보상 · 리그 준비 · 대진/플레이 방식 · 팀 관리/라인업 · 경기 조작 · 자동진행 · 결과/보상 | I5: 결과 기준 | J5: Pass / Fail / Blocked / N/A / Not Run
A6: 작성/판정 기준 | B6: 직접 확인한 화면·플레이 흐름과 동일 세션의 전후 상태 비교를 기준으로 작성 | I6: 앱/환경 | J6: Android 16 / One UI 8.5 · 앱 12.3.1 · Galaxy S23 Ultra
A7: 제외 범위 | B7: 결제 · 엔드 콘텐츠 · 장기 성장 루프 · 내부 정책/운영툴 · 무승부(DRAW) 결과 검증 · 현재 화면/플레이 흐름으로 확인되지 않은 기능 | I7: 주요 리스크 | J7: 앱 전환 · 경기개입 · 보상 반영 · 중복 입력 · 상태 유지 · UX 관찰 후보
A9: 대시보드 요약
A10: 총 TC | B10: 실행 완료 | C10: Pass | D10: Fail | E10: Blocked | F10: N/A | G10: Not Run | H10: 실행률 | I10: P1 실행률 | J10: 판정률 | K10: BTS 이슈 ID | N10: 비고
A11: =COUNTA($A$37:$A$171) -> 135 | B11: =COUNTIF($K$37:$K$171,"Pass")+COUNTIF($K$37:$K$171,"Fail")+COUNTIF($K$37:$K$171,"Blocked")+COUNTIF($K$37:$K$171,"N/A") -> 135 | C11: =COUNTIF($K$37:$K$171,"Pass") -> 133 | D11: =COUNTIF($K$37:$K$171,"Fail") -> 1 | E11: =COUNTIF($K$37:$K$171,"Blocked") -> 1 | F11: =COUNTIF($K$37:$K$171,"N/A") -> 0 | G11: =COUNTIF($K$37:$K$171,"Not Run") -> 0 | H11: =IFERROR(B11/A11,0) -> 1 | I11: =IFERROR((COUNTIFS($F$37:$F$171,"P1",$K$37:$K$171,"Pass")+COUNTIFS($F$37:$F$171,"P1",$K$37:$K$171,"Fail")+COUNTIFS($F$37:$F$171,"P1",$K$37:$K$171,"Blocked")+COUNTIFS($F$37:$F$171,"P1",$K$37:$K$171,"N/A"))/COUNTIF($F$37:$F$171,"P1"),0) -> 1 | J11: =IFERROR((C11+D11)/A11,0) -> 0.99259259 | K11: =COUNTA('BTS_증빙'!$A$5:$A$7) -> 3 | N11: ="리스크 TC: Pass "&COUNTIF($K$163:$K$171,"Pass")&" / Fail "&COUNTIF($K$163:$K$171,"Fail")&" / Blocked "&COUNTIF($K$163:$K$171,"Blocked")&" · 단위 분리 후 "&A11&"건" -> 리스크 TC: Pass 7 / Fail 1 / Blocked 1 · 단위 분리 후 135건
A12: 대표 검증 사례 AUTO-007 중복입력·P 차감 | RESULT-005-B 보상 합산 | RISK-005 네트워크 복구 | RISK-006 강제 종료 복구 | RISK-009 기록 초기화 오류
A13: TC 분포 및 검증·이슈 현황
A14: 대분류 | D14: 유형 | G14: 우선순위 | J14: 검증·이슈 현황 | M14: BTS 등록
A15: 앱/로비 | B15: =COUNTIF($B$37:$B$171,A15) -> 8 | D15: 정상 | E15: =COUNTIF($E$37:$E$171,D15) -> 84 | G15: P1 | H15: =COUNTIF($F$37:$F$171,G15) -> 44 | J15: 이슈 없음 TC | K15: =COUNTIFS($K$37:$K$171,"Pass",$L$37:$L$171,"-",$M$37:$M$171,"-") -> 128 | M15: {=IFERROR(INDEX('BTS_증빙'!$A$5:$A$7,1),"")} -> BUG-001 | N15: {=IFERROR(INDEX('BTS_증빙'!$C$5:$C$7,1),"")} -> Bug
A16: 환경설정 | B16: =COUNTIF($B$37:$B$171,A16) -> 31 | D16: 예외 | E16: =COUNTIF($E$37:$E$171,D16) -> 4 | G16: P2 | H16: =COUNTIF($F$37:$F$171,G16) -> 85 | J16: 관찰·후보 TC | K16: =COUNTIF($L$37:$L$171,"Observation")+COUNTIF($L$37:$L$171,"UX")+COUNTIF($L$37:$L$171,"Risk") -> 5 | M16: {=IFERROR(INDEX('BTS_증빙'!$A$5:$A$7,2),"")} -> OBS-001 | N16: {=IFERROR(INDEX('BTS_증빙'!$C$5:$C$7,2),"")} -> Observation/Risk
A17: 이벤트/보상 | B17: =COUNTIF($B$37:$B$171,A17) -> 12 | D17: 경계 | E17: =COUNTIF($E$37:$E$171,D17) -> 4 | G17: P3 | H17: =COUNTIF($F$37:$F$171,G17) -> 6 | J17: Need Spec TC | K17: =COUNTIF($L$37:$L$171,"Need Spec") -> 0 | M17: {=IFERROR(INDEX('BTS_증빙'!$A$5:$A$7,3),"")} -> UX-001 | N17: {=IFERROR(INDEX('BTS_증빙'!$C$5:$C$7,3),"")} -> UX/Observation
A18: 리그/경기 준비 | B18: =COUNTIF($B$37:$B$171,A18) -> 24 | D18: 상태전이 | E18: =COUNTIF($E$37:$E$171,D18) -> 22 | G18: 우선순위 합계 | H18: =SUM(H15:H17) -> 135 | J18: 재검증 필요 TC | K18: =COUNTIFS($K$37:$K$171,"Not Run",$L$37:$L$171,"<>Need Spec") -> 0 | M18: {=IFERROR(INDEX('BTS_증빙'!$A$5:$A$7,4),"")} | N18: {=IFERROR(INDEX('BTS_증빙'!$C$5:$C$7,4),"")}
A19: 팀 관리/라인업 | B19: =COUNTIF($B$37:$B$171,A19) -> 12 | D19: 지속성 | E19: =COUNTIF($E$37:$E$171,D19) -> 4 | G19: P1 실행률 | H19: =I11 -> 1 | J19: Fail·Blocked TC | K19: =COUNTIF($K$37:$K$171,"Fail")+COUNTIF($K$37:$K$171,"Blocked") -> 2 | M19: {=IFERROR(INDEX('BTS_증빙'!$A$5:$A$7,5),"")} | N19: {=IFERROR(INDEX('BTS_증빙'!$C$5:$C$7,5),"")}
A20: 경기 조작 | B20: =COUNTIF($B$37:$B$171,A20) -> 30 | D20: 복구 | E20: =COUNTIF($E$37:$E$171,D20) -> 7 | J20: BTS 이슈 ID | K20: =COUNTA('BTS_증빙'!$A$5:$A$7) -> 3
A21: 자동진행/경기개입 | B21: =COUNTIF($B$37:$B$171,A21) -> 12 | D21: 인터럽트 | E21: =COUNTIF($E$37:$E$171,D21) -> 3 | J21: 확인된 결함 TC | K21: =COUNTIF($L$37:$L$171,"Bug") -> 1
A22: 경기 결과/보상 | B22: =COUNTIF($B$37:$B$171,A22) -> 6 | D22: 중복입력 | E22: =COUNTIF($E$37:$E$171,D22) -> 7 | J22: BTS ID 입력 TC | K22: =COUNTIFS($M$37:$M$171,"<>-",$M$37:$M$171,"<>") -> 6
A23: 대분류 합계 | B23: =SUM(B15:B22) -> 135 | D23: 유형 합계 | E23: =SUM(E15:E22) -> 135 | J23: TC 상태 합계 | K23: =SUM(K15:K19) -> 135
A24: 분류 / 판정 기준
A25: 유형 기준 | C25: 정상: 기본 흐름 / 예외: 조건 불충족·비정상 입력 경계: 최소·최대·동일값 / 상태전이: 설정·화면·진행 변경 지속성: 재진입·재실행 후 유지 / 복구: 종료·네트워크 전환 후 복귀 인터럽트: 앱 전환·백그라운드 / 중복입력: 연속·반복 입력 | G25: 우선순위 기준 | I25: P1: 앱·경기 핵심 진행, 결과·보상·재화·저장 / P2: 주요 기능·설정·팀 관리·복구 / P3: 단순 표시·문구·낮은 영향도
A26: 결함 기준 | C26: 확인된 결함은 이슈유형이 [Bug]인 TC로 집계하며, BTS 등록 현황은 BTS 이슈 열에 BUG-/DEF- ID가 입력된 TC 수로 관리 | G26: 관찰 후보 | I26: OBS/UX 후보는 확정 결함과 분리하고, BTS 이슈 열의 후보 ID로 별도 관리
A27: 기대결과 근거 | C27: 기대결과는 화면 표시, 조작 반응, 전후 상태 비교, 반복 확인을 기준으로 작성함. 상세 기능 TC는 1행 1핵심 판정 목적을 원칙으로 하며, Smoke·End-to-End 흐름은 예외로 관리함. | G27: 판정 기준 | I27: Pass: 직접 실행 후 기대결과와 일치 / Fail: 직접 실행 후 불일치 / Blocked: 조건 구성 불가 / Not Run: 재검증 필요 / N/A: 범위 제외 / Need Spec: 화면과 직접 플레이만으로 기준 확인이 어려운 항목
A28: Test Environment · 테스트 환경
A29: 플랫폼 | B29: Android / Mobile | C29: 기기명 | D29: Galaxy S23 Ultra | E29: 모델명 | F29: SM-S918N | G29: OS | H29: Android 16 / One UI 8.5 | I29: 입력 방식 | J29: 터치 | K29: 화면 방향 | L29: 가로 고정
A30: 네트워크 | B30: 5G / SKTelecom | C30: 앱 버전 | D30: 12.3.1 | E30: 테스트 일자 | F30: 46214 | G30: 테스트 범위 | H30: 리그 초반 플레이 루프 | I30: 테스트 계정 | J30: 개인 일반 계정 | K30: 게임 언어 | L30: 한국어
A31: 보안 패치 | B31: 2026-06-05 | C31: 화면/글꼴 | D31: FHD+ 2316×1080 / 글꼴 기본값 / 화면 크기 기본값 | E31: 그래픽/사운드 | F31: 기본값 기준 | G31: 리그 상태 | H31: 초반 리그 진행 | I31: 재화 기준 | J31: 화면 표시값 비교 | K31: 테스트 기준 | L31: 직접 플레이 시점
A36: TC ID | B36: 대분류 | C36: 중분류 | D36: 소분류 | E36: 유형 | F36: 우선순위 | G36: 테스트 사전조건 | H36: 테스트 데이터/조건 | I36: 테스트 수행방법 | J36: 기대결과 | K36: 테스트 결과 | L36: 이슈유형 | M36: BTS 이슈 | N36: 비고
A37: CPB26-APP-001 | B37: 앱/로비 | C37: 앱 진입 | D37: 앱 실행·로비 진입 Smoke | E37: 정상 | F37: P1 | G37: 앱이 설치되어 있고 테스트 계정 로그인이 완료된 상태에서 앱이 종료되어 있음 | H37: 앱 버전 12.3.1 / Android 16 / 가로 화면 / 네트워크 정상 연결 | I37: 1. 앱 아이콘을 1회 탭해 앱을 실행한다. 2. 로딩 화면이 종료될 때까지 기다린다. 3. 로비 화면이 표시되는지 확인한다. 4. 로비의 계정·재화 정보 영역과 주요 메뉴 영역이 함께 표시되는지 확인한다. 5. 화면 방향이 가로로 유지되는지 확인한다. | J37: 로딩 종료 후 가로 방향의 로비 화면이 표시되어야 한다. 로비 상단의 계정·재화 정보 영역과 주요 메뉴 영역이 함께 표시되어야 하며, 빈 화면·무한 로딩·비정상 종료·세로 화면 전환이 발생하지 않아야 한다. | K37: Pass | L37: - | M37: - | N37: Smoke 확인. 세부 메뉴와 수치 검증은 기능별 TC에서 분리.
A38: CPB26-APP-002 | B38: 앱/로비 | C38: 상단 정보 | D38: 상단 정보 표시 | E38: 정상 | F38: P2 | G38: 로비 화면에 진입한 상태 | H38: 팀전력 수치 / 야구공 수량 / P 수량 / 스타 수량이 표시되는 상단 정보 영역 | I38: 1. 로비 화면 상단 정보 영역을 확인한다. 2. 팀전력 수치와 아이콘이 표시되는지 확인한다. 3. 야구공 수량과 아이콘이 표시되는지 확인한다. 4. P 수량과 스타 수량이 각각 표시되는지 확인한다. 5. 각 아이콘과 수치가 겹치거나 잘리지 않는지 확인한다. | J38: 로비 상단 정보 영역에 팀전력, 야구공, P, 스타의 아이콘과 현재 수량 또는 수치가 각각 표시되어야 한다. 각 값은 항목별로 구분되고 화면 밖으로 잘리거나 다른 UI에 가려지지 않아야 한다. | K38: Pass | L38: - | M38: -
A39: CPB26-APP-003 | B39: 앱/로비 | C39: 홈 이동 | D39: HOME 버튼 표시 | E39: 정상 | F39: P3 | G39: 환경설정 화면에 진입한 상태 | H39: 화면 좌측 상단 [HOME] 버튼 | I39: 1. 환경설정 화면 좌측 상단을 확인한다. 2. [HOME] 버튼의 집 모양 아이콘과 HOME 문구가 함께 표시되는지 확인한다. 3. 아이콘 또는 문구가 화면 밖으로 잘리거나 다른 UI와 겹치지 않는지 확인한다. | J39: 환경설정 화면 좌측 상단에 집 모양 아이콘과 HOME 문구가 포함된 [HOME] 버튼이 표시되어야 한다. 버튼의 아이콘과 문구는 모두 읽을 수 있어야 한다. | K39: Pass | L39: - | M39: -
A40: CPB26-APP-004 | B40: 앱/로비 | C40: 채팅/공지 | D40: 채팅·공지 배너 | E40: 정상 | F40: P3 | G40: 로비 화면에 진입한 상태 | H40: 화면 상단 중앙의 말풍선 아이콘과 한 줄 텍스트 배너 | I40: 1. 로비 화면 상단 중앙 영역을 확인한다. 2. 말풍선 아이콘이 표시되는지 확인한다. 3. 아이콘 옆에 한 줄 텍스트 배너가 표시되는지 확인한다. 4. 텍스트가 이동하는 경우 문구가 배너 영역 안에서 판독 가능한지 확인한다. 5. 배너가 상단 재화 정보나 주요 버튼을 가리지 않는지 확인한다. | J40: 로비 상단 중앙에 말풍선 아이콘과 한 줄 텍스트 배너가 표시되어야 한다. 배너 문구는 지정된 영역 안에서 판독 가능해야 하며 상단 재화 정보와 주요 버튼을 가리지 않아야 한다. | K40: Pass | L40: - | M40: -
A41: CPB26-APP-005 | B41: 앱/로비 | C41: 이벤트 팝업 | D41: 접속 보상 팝업 | E41: 정상 | F41: P2 | G41: 앱 접속 직후 보상 팝업이 자동 노출된 상태 | H41: 테스트 시 노출된 접속 보상 팝업 1종 / 보상 아이콘 / 수령 상태 표시 / [확인] 버튼 | I41: 1. 접속 보상 팝업의 제목 또는 보상판 영역을 확인한다. 2. 지급 대상 보상 아이콘과 수량이 표시되는지 확인한다. 3. 이미 수령한 항목과 미수령 항목의 상태가 구분되는지 확인한다. 4. 팝업 하단에 [확인] 버튼이 표시되는지 확인한다. 5. 보상 정보와 버튼 문구가 겹치거나 잘리지 않는지 확인한다. | J41: 접속 보상 팝업에 보상 아이콘과 수량, 수령 상태, [확인] 버튼이 표시되어야 한다. 수령 상태는 항목별로 구분되어야 하며 보상 정보와 버튼 문구가 서로 겹치거나 잘리지 않아야 한다. | K41: Pass | L41: - | M41: - | N41: 앱 최초 진입 과정에서 자동 노출되는 보상 팝업 기준.
A42: CPB26-APP-006 | B42: 앱/로비 | C42: 이벤트 팝업 | D42: 접속 보상 팝업 종료 후 입력 차단 해제 | E42: 복구 | F42: P2 | G42: 접속 보상 팝업에 [확인] 버튼이 표시된 상태 | H42: [확인] 버튼 / 팝업 뒤에 로비 화면이 표시된 상태 | I42: 1. 접속 보상 팝업 하단의 [확인] 버튼을 1회 탭한다. 2. 팝업이 화면에서 사라지는지 확인한다. 3. 팝업 뒤의 로비 화면이 표시되는지 확인한다. 4. 로비의 주요 메뉴 버튼 1개를 탭해 입력이 정상 처리되는지 확인한다. 5. 확인한 메뉴에서 뒤로가기를 사용해 로비로 복귀한다. | J42: [확인] 버튼 입력 후 접속 보상 팝업이 닫히고 로비 화면이 표시되어야 한다. 팝업이 투명한 입력 차단 상태로 남지 않아야 하며 로비의 주요 메뉴 버튼을 정상적으로 선택할 수 있어야 한다. | K42: Pass | L42: - | M42: - | N42: 팝업 종료 후 로비 입력 가능 상태 확인.
A43: CPB26-APP-007 | B43: 앱/로비 | C43: 개인정보 링크 | D43: 약관·개인정보 버튼 | E43: 정상 | F43: P3 | G43: 환경설정 화면에 진입한 상태 | H43: 우측 하단 `이용약관 및 개인정보 처리 방침` 버튼 표시 | I43: 1. 환경설정 화면 우측 하단을 확인한다. 2. `이용약관 및 개인정보 처리 방침` 버튼이 표시되는지 확인한다. 3. 버튼 문구가 줄바꿈되더라도 판독 가능한지 확인한다. | J43: 이용약관 및 개인정보 처리 방침 버튼은 환경설정 화면 우측 하단에 표시된다. 문구가 잘리거나 다른 버튼과 겹치지 않아야 한다. | K43: Pass | L43: - | M43: -
A44: CPB26-APP-008 | B44: 앱/로비 | C44: 개인정보 링크 | D44: 인앱 약관 화면 이동·복귀 | E44: 정상 | F44: P3 | G44: 환경설정 화면 우측 하단에 [이용약관 및 개인정보 처리 방침] 버튼이 표시된 상태 | H44: [이용약관 및 개인정보 처리 방침] 버튼 / 인앱 전용 약관 화면 / Android 뒤로가기 | I44: 1. [이용약관 및 개인정보 처리 방침] 버튼을 1회 탭한다. 2. 외부 인터넷 브라우저가 별도로 실행되지 않고 인앱 전용 약관 화면으로 이동하는지 확인한다. 3. 약관 문구가 표시되고 빈 화면·무한 로딩·중복 화면이 발생하지 않는지 확인한다. 4. Android 뒤로가기를 입력해 환경설정 화면으로 복귀되는지 확인한다. | J44: 버튼 입력 후 인앱 전용 약관 화면으로 정상 이동해야 한다. 약관 문구를 확인할 수 있어야 하며, 빈 화면·무한 로딩·중복 화면이 발생하지 않아야 한다. 뒤로가기 입력 후 환경설정 화면으로 복귀해야 한다. | K44: Pass | L44: - | M44: - | N44: 인앱 전용 약관 화면 이동과 뒤로가기 복귀 흐름 확인.
A45: CPB26-SET-001 | B45: 환경설정 | C45: 탭 구조 | D45: 환경설정 탭 | E45: 정상 | F45: P2 | G45: 환경설정 화면에 진입한 상태 | H45: 사운드 / 그래픽 / 게임 설정 / 게임 문의 / 알림 설정 탭 | I45: 1. 환경설정 화면 상단 탭 영역을 확인한다. 2. 사운드, 그래픽, 게임 설정, 게임 문의, 알림 설정 탭이 표시되는지 확인한다. 3. 선택된 탭과 비선택 탭의 표시 상태가 구분되는지 확인한다. | J45: 환경설정 화면에는 5개 탭이 가로로 표시된다. 현재 선택된 탭은 다른 탭과 구분되어야 하며, 탭 문구가 잘리지 않아야 한다. | K45: Pass | L45: - | M45: -
A46: CPB26-SET-002 | B46: 환경설정 | C46: 사운드 | D46: 사운드 항목 | E46: 정상 | F46: P2 | G46: 환경설정 화면에서 사운드 탭을 선택한 상태 | H46: 배경음 / 효과음 / 캐스터·해설 / 응원가 항목의 슬라이더와 현재 수치 | I46: 1. 환경설정 상단에서 [사운드] 탭을 1회 탭한다. 2. [배경음], [효과음], [캐스터·해설], [응원가] 항목이 각각 표시되는지 확인한다. 3. 각 항목에 슬라이더가 표시되는지 확인한다. 4. 각 슬라이더 옆에 현재 볼륨 수치가 표시되는지 확인한다. 5. 항목명, 슬라이더, 수치가 겹치거나 잘리지 않는지 확인한다. | J46: [사운드] 탭에 배경음, 효과음, 캐스터·해설, 응원가 4개 볼륨 항목이 표시되어야 한다. 각 항목에는 슬라이더와 현재 수치가 함께 표시되고 모든 문구와 수치가 읽을 수 있어야 한다. | K46: Pass | L46: - | M46: -
...

Sheet BTS_증빙
A1: BTS 이슈 / 주요 TC 직접 플레이 증빙
A2: 확정 결함, 관찰·UX 후보와 주요 기능 TC의 직접 플레이 근거를 정리함. 확정 결함은 최상단에 배치하고 Jira 등록 시 BTS ID를 연계 관리함.
A4: 이슈 ID | B4: 관련 TC ID | C4: 분류 | D4: 이슈/관찰 내용 | E4: 기대/확인 기준 | F4: 재현 절차 | G4: 재현율 | H4: 실행 환경 | I4: 증빙 메모·BTS ID | J4: 상태
A5: BUG-001 | B5: CPB26-RISK-009 | C5: Bug | D5: 신규 하드 리그 첫 경기에서 타석 기록이 없는 상대 타자의 출루율과 OPS가 1.000으로 표시됨. 동일 조건의 사용자 팀은 0으로 표시되며, 두 번째 경기에서는 동일 상대 선수의 출루율과 OPS가 0.500으로 표시됨. | E5: 신규 리그 무기록 상태의 출루율과 OPS는 0 또는 무기록으로 양 팀 동일 기준으로 표시되어야 한다. 경기 결과 반영 후에는 실제 출루 기록에 따라 계산되어야 한다. | F5: 신규 하드 리그 시작 → 첫 경기 사용자 팀·상대 팀 첫 타석 전 기록 비교 → 상대 선수 3명 이상 확인 → 두 번째 경기 동일 선수 기록 재확인 | G5: 신규 리그 1회 / 상대 선수 다수 반복 확인 | H5: Galaxy S23 Ultra / Android 16 / One UI 8.5 / 앱 12.3.1 | I5: BUG-001-E01~E04 화면 이미지 연결 / Jira KAN-4 등록 완료 | J5: Fail · Jira 연계
A6: OBS-001 | B6: CPB26-MATCH-010 / CPB26-MATCH-011 / CPB26-PITCH-012 / CPB26-PITCH-013 | C6: Observation/Risk | D6: 공격·수비의 조작 구간에 따라 일시정지 버튼 노출과 앱 전환 복귀 방식이 다르게 처리됨. | E6: 상태별 복귀 방식이 일관되게 처리되고, 복귀 후 화면 멈춤·입력 불가·UI 깨짐이 없어야 함. | F6: 공격 교체 가능 구간, 공격 투구 직전 구간, 수비 구종 선택 구간, 수비 투구 위치 선택 구간을 나누어 앱 전환 후 복귀 결과를 확인. | G6: 핵심 구간별 2~3회 반복 확인 | H6: Galaxy S23 Ultra / Android 16 / One UI 8.5 / 앱 12.3.1 | I6: OBS-001-E01~E05 화면 이미지와 반복 확인 내용 연결 | J6: 관찰 후보
A7: UX-001 | B7: CPB26-BAT-005 | C7: UX/Observation | D7: L번트와 R번트 입력에서 서로 다른 타구 방향이 관찰됨. 라이브 경기 특성상 동일 타자·동일 구종·동일 투구 위치 조건은 통제하기 어려움. | E7: TC Pass 기준은 L/R 버튼 입력 정상 처리와 조작 안정성이다. 타구 방향 차이와 번트 성공 여부는 UX 관찰로 별도 관리한다. | F7: 서로 다른 타격 기회에서 L번트와 R번트를 각각 실행하고 버튼 입력 처리, 경기 진행, 타구 방향을 확인한다. | G7: L/R 각 1회 이상 직접 확인 | H7: Galaxy S23 Ultra / Android 16 / One UI 8.5 / 앱 12.3.1 | I7: UX-001-E01~E03 화면 이미지와 관찰 내용 연결 | J7: UX 후보
A8: BUG-001 직접 플레이 증빙 · 신규 하드 리그 상대 타자 출루율·OPS 표시
A9: 증빙 ID | B9: 관련 TC ID | C9: 판정 | D9: 확인 조건 | E9: 관찰 결과 | F9: 이미지 설명 | G9: 이미지
A10: BUG-001-E01 | B10: CPB26-RISK-009 | C10: Fail | D10: 신규 하드 리그 1경기 / 사용자 팀 첫 타석 전 | E10: 타율·안타·출루율·장타율·OPS가 모두 0으로 표시됨. | F10: 사용자 팀 무기록 초기값 0
A11: BUG-001-E02 | B11: CPB26-RISK-009 | C11: Fail | D11: 신규 하드 리그 1경기 / 상대 팀 첫 타석 전 | E11: 타율·안타·장타율은 0이나 출루율과 OPS가 1.000으로 표시됨. | F11: 상대 팀 첫 타석 전 1.000
A12: BUG-001-E03 | B12: CPB26-RISK-009 | C12: Fail | D12: 신규 하드 리그 1경기 / 다른 상대 선수 첫 타석 전 | E12: 다른 상대 선수도 출루율과 OPS가 1.000으로 동일하게 표시됨. | F12: 상대 선수 다수 반복 1.000
A13: BUG-001-E04 | B13: CPB26-RISK-009 | C13: 보강 | D13: 신규 하드 리그 2경기 / 동일 상대 선수 | E13: 첫 경기 1.000이었던 동일 선수의 출루율과 OPS가 두 번째 경기에서 0.500으로 표시됨. | F13: 두 번째 경기 0.500 추가 관찰
A15: OBS-001 관찰 연결 표 · 앱 전환/일시정지 상태별 관찰
A16: 관찰 ID | B16: 후보 ID | C16: 구간 | D16: 화면 상태 | E16: 관찰 결과 | F16: 이미지 설명 | G16: 이미지
A17: OBS-001-E01 | B17: OBS-001 | C17: 공격 / 교체 가능 구간 | D17: 타자 적용 효과 화면, 일시정지 버튼 표시 | E17: 앱 전환 후 일시정지 메뉴로 복귀되는 흐름을 반복 확인 | F17: 공격 교체 가능 구간
A18: OBS-001-E02 | B18: OBS-001 | C18: 공격 / 앱 복귀 | D18: 일시정지 메뉴 표시 | E18: 반복 확인 시 [계속 하기] 등 일시정지 메뉴가 동일하게 표시됨 | F18: 앱 복귀 후 일시정지 메뉴
A19: OBS-001-E03 | B19: OBS-001 | C19: 공격 / 투구 직전 | D19: 일시정지 버튼 미표시 | E19: 반복 확인 시 메뉴 없이 투구·타격 흐름으로 이어짐 | F19: 타격 진행 구간
A20: OBS-001-E04 | B20: OBS-001 | C20: 수비 / 구종 선택 | D20: 구종 버튼과 일시정지 버튼 표시 | E20: 반복 확인 시 수비 구종 선택 구간에서 일시정지 가능 상태 유지 | F20: 수비 구종 선택
A21: OBS-001-E05 | B21: OBS-001 | C21: 수비 / 투구 위치 선택 | D21: 투구 위치 조정 UI, 일시정지 버튼 미표시 | E21: 1분 대기와 앱 전환 반복 확인 후에도 위치 선택 상태 유지 | F21: 수비 투구 위치 선택
A23: UX-001 관찰 연결 표 · L/R 번트 방향 및 경기 흐름 제약
A24: 관찰 ID | B24: 후보 ID | C24: 구간 | D24: 화면 상태 | E24: 관찰 결과 | F24: 이미지 설명 | G24: 이미지
A25: UX-001-E01 | B25: UX-001 | C25: 번트 / L 선택 | D25: [L번트] 선택 상태 | E25: 좌측 방향 번트 시도 관찰 | F25: L번트 선택
A26: UX-001-E02 | B26: UX-001 | C26: 번트 / R 선택·진행 | D26: [R번트] 선택 또는 타격 진행 상태 | E26: 우측 방향 번트 시도와 타구 결과 기록 대상 | F26: R번트 선택/진행
A27: UX-001-E03 | B27: UX-001 | C27: 번트 / 반복 결과 | D27: 다른 타자 조건의 번트 시도 화면 | E27: 파울, 투수 앞 타구, 포수 처리, 뜬공 등 결과 기록 대상 | F27: 반복 시도 결과
A29: PITCH-010 직접 플레이 증빙 · 수동 제구 타이밍 판정
A30: 증빙 ID | B30: 관련 TC ID | C30: 판정 | D30: 확인 조건 | E30: 관찰 결과 | F30: 이미지 설명 | G30: 이미지
A31: PITCH-010-E01 | B31: CPB26-PITCH-010 | C31: Perfect | D31: 수동 제구 / 1경기 반복 확인 | E31: Perfect 문구 표시 후 투구와 경기 진행이 정상적으로 이어짐. | F31: Perfect 판정 1
A32: PITCH-010-E02 | B32: CPB26-PITCH-010 | C32: Perfect | D32: 수동 제구 / 1경기 반복 확인 | E32: 다른 타석에서도 Perfect 문구와 후속 투구 진행을 확인함. | F32: Perfect 판정 2
A33: PITCH-010-E03 | B33: CPB26-PITCH-010 | C33: Great | D33: 입력 타이밍 변경 | E33: Great 문구 표시 후 투구와 경기 진행이 정상적으로 이어짐. | F33: Great 판정
A34: PITCH-010-E04 | B34: CPB26-PITCH-010 | C34: Good | D34: 입력 타이밍 변경 | E34: Good 문구 표시 후 투구와 경기 진행이 정상적으로 이어짐. | F34: Good 판정
A35: PITCH-010-E05 | B35: CPB26-PITCH-010 | C35: Bad | D35: 입력 타이밍 변경 | E35: Bad 문구 표시 후에도 투구와 경기 진행이 정상적으로 이어짐. 판정별 결과 차이는 본 TC 범위에서 제외함. | F35: Bad 판정
A39: 관찰·UX 후보 직접 플레이 비교 메모
A40: 후보 ID | B40: 회차 | C40: 조건 | D40: 입력 | E40: 관찰 결과 | F40: 판정 메모
A41: OBS-001 | B41: 2~3회 반복 | C41: 공격 교체 가능 구간 | D41: 앱 전환 후 복귀 | E41: 일시정지 메뉴 표시 | F41: 화면 멈춤 없음
A42: OBS-001 | B42: 2~3회 반복 | C42: 공격 투구 직전 | D42: 앱 전환 후 복귀 | E42: 메뉴 없이 경기 진행 | F42: 공이 바로 날아옴
A43: OBS-001 | B43: 2~3회 반복 | C43: 수비 위치 선택 | D43: 1분 대기 + 앱 전환 | E43: 위치 선택 상태 유지 | F43: 자동 투구 없음
A44: UX-001 | B44: 1회 | C44: 유사 조건 | D44: L번트 선택 | E44: 좌측 방향 타구 | F44: 방향 차이 확인
A45: UX-001 | B45: 1회 | C45: 유사 조건 | D45: R번트 선택 | E45: 우측 방향 타구 | F45: 방향 차이 확인
